<?xml version="1.0" ?>
<!-- =================================================================================== -->
<!-- |    This document was autogenerated by xacro from urdf/xacro/mybot.urdf.xacro    | -->
<!-- |    EDITING THIS FILE BY HAND IS NOT RECOMMENDED                                 | -->
<!-- =================================================================================== -->
<robot name="mybot" xmlns:xacro="http://www.ros.org/wiki/xacro">
  <!-- BASE -->
  <link name="base_footprint"/>
  <joint name="base_footprint_joint" type="fixed">
    <parent link="base_footprint"/>
    <child link="base_mobile"/>
    <origin rpy="0 0 0" xyz="0 0 0"/>
  </joint>
  <link name="base_mobile">
    <visual>
      <geometry>
        <mesh filename="package://mybot_description/dae/base_mobile.dae"/>
      </geometry>
      <material name="gray">
        <color rgba="0.8 0.8 0.8 1"/>
      </material>
    </visual>
    <collision>
      <geometry>
        <mesh filename="package://mybot_description/dae/base_mobile.dae"/>
      </geometry>
    </collision>
  </link>
  <joint name="base_mobile_joint" type="fixed">
    <parent link="base_mobile"/>
    <child link="base_wheel"/>
    <origin rpy="0 0 0" xyz="0 0 0.103"/>
  </joint>
  <link name="base_wheel"/>
  <joint name="base_joint" type="fixed">
    <parent link="base_mobile"/>
    <child link="base_0"/>
    <origin rpy="0 0 0" xyz="0 0 0.497"/>
  </joint>
  <link name="base_0">
    <visual>
      <geometry>
        <mesh filename="package://mybot_description/dae/base_0.dae"/>
      </geometry>
      <material name="gray">
        <color rgba="0.8 0.8 0.8 1"/>
      </material>
    </visual>
    <collision>
      <geometry>
        <mesh filename="package://mybot_description/dae/base_0.dae"/>
      </geometry>
    </collision>
  </link>
  <joint name="hokuyo_joint" type="fixed">
    <parent link="base_mobile"/>
    <child link="hokuyo_link"/>
    <origin rpy="0 0 0" xyz="0.17062 0 0.239"/>
  </joint>
  <link name="hokuyo_link"/>
  <!-- MOBILE PLATFORM -->
  <joint name="wheel_temp_joint_0" type="fixed">
    <parent link="base_wheel"/>
    <child link="wheel_temp_0"/>
    <origin rpy="0 0 1.0471975512" xyz="0 0 0"/>
  </joint>
  <link name="wheel_temp_0"/>
  <joint name="wheel_temp_joint_1" type="fixed">
    <parent link="base_wheel"/>
    <child link="wheel_temp_1"/>
    <origin rpy="0 0 -1.0471975512" xyz="0 0 0"/>
  </joint>
  <link name="wheel_temp_1"/>
  <joint name="wheel_temp_joint_2" type="fixed">
    <parent link="base_wheel"/>
    <child link="wheel_temp_2"/>
    <origin rpy="0 0 -3.14159265359" xyz="0 0 0"/>
  </joint>
  <link name="wheel_temp_2"/>
  <joint name="wheel_joint_0" type="continuous">
    <parent link="wheel_temp_0"/>
    <child link="wheel_0"/>
    <origin rpy="0 0 0" xyz="0.2752 0 0"/>
    <limit effort="7.0" velocity="1.0471975512"/>
    <safety_controller k_velocity="0.94247779608"/>
    <dynamics damping="1.0" friction="0.0"/>
  </joint>
  <link name="wheel_0">
    <visual>
      <geometry>
        <mesh filename="package://mybot_description/dae/wheel.dae"/>
      </geometry>
      <material name="gray">
        <color rgba="0.8 0.8 0.8 1"/>
      </material>
    </visual>
    <collision>
      <geometry>
        <mesh filename="package://mybot_description/dae/wheel.dae"/>
      </geometry>
    </collision>
  </link>
  <joint name="wheel_joint_1" type="continuous">
    <parent link="wheel_temp_1"/>
    <child link="wheel_1"/>
    <origin rpy="0 0 0" xyz="0.2752 0 0"/>
    <limit effort="7.0" velocity="1.0471975512"/>
    <safety_controller k_velocity="0.94247779608"/>
    <dynamics damping="1.0" friction="0.0"/>
  </joint>
  <link name="wheel_1">
    <visual>
      <geometry>
        <mesh filename="package://mybot_description/dae/wheel.dae"/>
      </geometry>
      <material name="gray">
        <color rgba="0.8 0.8 0.8 1"/>
      </material>
    </visual>
    <collision>
      <geometry>
        <mesh filename="package://mybot_description/dae/wheel.dae"/>
      </geometry>
    </collision>
  </link>
  <joint name="wheel_joint_2" type="continuous">
    <parent link="wheel_temp_2"/>
    <child link="wheel_2"/>
    <origin rpy="0 0 0" xyz="0.2752 0 0"/>
    <limit effort="7.0" velocity="1.0471975512"/>
    <safety_controller k_velocity="0.94247779608"/>
    <dynamics damping="1.0" friction="0.0"/>
  </joint>
  <link name="wheel_2">
    <visual>
      <geometry>
        <mesh filename="package://mybot_description/dae/wheel.dae"/>
      </geometry>
      <material name="gray">
        <color rgba="0.8 0.8 0.8 1"/>
      </material>
    </visual>
    <collision>
      <geometry>
        <mesh filename="package://mybot_description/dae/wheel.dae"/>
      </geometry>
    </collision>
  </link>
  <!-- WAIST -->
  <joint name="waist_joint_0" type="revolute">
    <parent link="base_0"/>
    <child link="waist_0"/>
    <axis xyz="0 0 1"/>
    <origin rpy="0 0 0" xyz="0 0 0"/>
    <limit effort="30.0" lower="-0.785398163397" upper="0.785398163397" velocity="0.418879020479"/>
    <dynamics damping="10.0"/>
  </joint>
  <link name="waist_0">
    <visual>
      <geometry>
        <mesh filename="package://mybot_description/dae/waist_0.dae"/>
      </geometry>
      <material name="gray">
        <color rgba="0.8 0.8 0.8 1"/>
      </material>
    </visual>
    <collision>
      <geometry>
        <mesh filename="package://mybot_description/dae/waist_0.dae"/>
      </geometry>
    </collision>
  </link>
  <joint name="waist_joint_1" type="revolute">
    <parent link="waist_0"/>
    <child link="waist_1"/>
    <axis xyz="0 -1 0"/>
    <origin rpy="0 0 0" xyz="0 0 0.099"/>
    <limit effort="30.0" lower="-0.523598775598" upper="0.523598775598" velocity="0.418879020479"/>
    <dynamics damping="10.0"/>
  </joint>
  <link name="waist_1">
    <visual>
      <geometry>
        <mesh filename="package://mybot_description/dae/waist_1.dae"/>
      </geometry>
      <material name="gray">
        <color rgba="0.8 0.8 0.8 1"/>
      </material>
    </visual>
    <collision>
      <geometry>
        <mesh filename="package://mybot_description/dae/waist_1.dae"/>
      </geometry>
    </collision>
  </link>
  <!-- HEAD -->
  <joint name="head_mount_joint" type="fixed">
    <parent link="waist_1"/>
    <child link="head_mount"/>
    <origin rpy="0 0 0" xyz="0 0 0.398"/>
  </joint>
  <link name="head_mount">
    <visual>
      <geometry>
        <mesh filename="package://mybot_description/dae/head_mount.dae"/>
      </geometry>
      <material name="gray">
        <color rgba="0.8 0.8 0.8 1"/>
      </material>
    </visual>
    <collision>
      <geometry>
        <mesh filename="package://mybot_description/dae/head_mount.dae"/>
      </geometry>
    </collision>
  </link>
  <joint name="head_joint_0" type="revolute">
    <parent link="head_mount"/>
    <child link="head_0"/>
    <axis xyz="0 0 1"/>
    <origin rpy="0 0 0" xyz="0 0 0"/>
    <limit effort="30.0" lower="-1.13" upper="1.13" velocity="0.418879020479"/>
    <dynamics damping="10.0"/>
  </joint>
  <link name="head_0">
    <visual>
      <geometry>
        <mesh filename="package://mybot_description/dae/head_0.dae"/>
      </geometry>
      <material name="gray">
        <color rgba="0.8 0.8 0.8 1"/>
      </material>
    </visual>
    <collision>
      <geometry>
        <mesh filename="package://mybot_description/dae/head_0.dae"/>
      </geometry>
    </collision>
  </link>
  <joint name="head_joint_1" type="revolute">
    <parent link="head_0"/>
    <child link="head_1"/>
    <axis xyz="0 1 0"/>
    <origin rpy="0 0 0" xyz="0 0 0.075"/>
    <limit effort="30.0" lower="-0.34" upper="1.04" velocity="0.418879020479"/>
    <dynamics damping="10.0"/>
  </joint>
  <link name="head_1">
    <visual>
      <geometry>
        <mesh filename="package://mybot_description/dae/head_1.dae"/>
      </geometry>
      <material name="gray">
        <color rgba="0.8 0.8 0.8 1"/>
      </material>
    </visual>
    <collision>
      <geometry>
        <mesh filename="package://mybot_description/dae/head_1.dae"/>
      </geometry>
    </collision>
  </link>
  <joint name="head_joint_2" type="revolute">
    <parent link="head_1"/>
    <child link="head_2"/>
    <axis xyz="0 -1 0"/>
    <origin rpy="0 0 0" xyz="0 0 0.080"/>
    <limit effort="30.0" lower="-0.13" upper="0.13" velocity="0.418879020479"/>
    <dynamics damping="10.0"/>
  </joint>
  <link name="head_2">
    <visual>
      <geometry>
        <mesh filename="package://mybot_description/dae/head_2.dae"/>
      </geometry>
      <material name="gray">
        <color rgba="0.8 0.8 0.8 1"/>
      </material>
    </visual>
    <collision>
      <geometry>
        <mesh filename="package://mybot_description/dae/head_2.dae"/>
      </geometry>
    </collision>
  </link>
  <joint name="head_joint_3" type="revolute">
    <parent link="head_2"/>
    <child link="head_3"/>
    <axis xyz="-1 0 0"/>
    <origin rpy="0 0 0" xyz="0 0.0015 0"/>
    <limit effort="30.0" lower="-0.08" upper="0.08" velocity="0.418879020479"/>
    <dynamics damping="10.0"/>
  </joint>
  <link name="head_3">
    <visual>
      <geometry>
        <mesh filename="package://mybot_description/dae/head_3.dae"/>
      </geometry>
      <material name="gray">
        <color rgba="0.8 0.8 0.8 1"/>
      </material>
    </visual>
    <collision>
      <geometry>
        <mesh filename="package://mybot_description/dae/head_3.dae"/>
      </geometry>
    </collision>
  </link>
  <joint name="head_rgbd_sensor" type="fixed">
    <parent link="head_3"/>
    <child link="xtion_link"/>
    <origin rpy="0.0 0.0 0.0" xyz="0.049 -0.02 0.02"/>
  </joint>
  <link name="xtion_link"/>
  <joint name="xtion_depth_joint" type="fixed">
    <parent link="xtion_link"/>
    <child link="xtion_depth_frame"/>
    <origin rpy="0 0 0" xyz="0 0.0 0"/>
  </joint>
  <link name="xtion_depth_frame"/>
  <joint name="xtion_depth_optical_joint" type="fixed">
    <parent link="xtion_depth_frame"/>
    <child link="xtion_depth_optical_frame"/>
    <origin rpy="-1.57079632679 0 -1.57079632679" xyz="0 0 0"/>
  </joint>
  <link name="xtion_depth_optical_frame"/>
  <joint name="xtion_rgb_joint" type="fixed">
    <parent link="xtion_link"/>
    <child link="xtion_rgb_frame"/>
    <origin rpy="0 0 0" xyz="0 0.0 0"/>
  </joint>
  <link name="xtion_rgb_frame"/>
  <joint name="xtion_rgb_optical_joint" type="fixed">
    <parent link="xtion_rgb_frame"/>
    <child link="xtion_rgb_optical_frame"/>
    <origin rpy="-1.57079632679 0 -1.57079632679" xyz="0 0 0"/>
  </joint>
  <link name="xtion_rgb_optical_frame"/>
  <!-- RIGHT ARM -->
  <joint name="right_shoulder_joint_0" type="revolute">
    <parent link="waist_1"/>
    <child link="right_shoulder_0"/>
    <axis xyz="0 0 1"/>
    <origin rpy="0 0 0" xyz="0 -0.075 0.351"/>
    <limit effort="30.0" lower="-1.0471975512" upper="1.0471975512" velocity="0.418879020479"/>
    <dynamics damping="10.0"/>
  </joint>
  <link name="right_shoulder_0">
    <visual>
      <geometry>
        <mesh filename="package://mybot_description/dae/right_shoulder_0.dae"/>
      </geometry>
      <material name="gray">
        <color rgba="0.8 0.8 0.8 1"/>
      </material>
    </visual>
    <collision>
      <geometry>
        <mesh filename="package://mybot_description/dae/right_shoulder_0.dae"/>
      </geometry>
    </collision>
  </link>
  <joint name="right_shoulder_joint_1" type="revolute">
    <parent link="right_shoulder_0"/>
    <child link="right_shoulder_1"/>
    <axis xyz="0 -1 0"/>
    <origin rpy="0 0 0" xyz="0 0 0"/>
    <limit effort="30.0" lower="-1.57079632679" upper="2.09439510239" velocity="0.418879020479"/>
    <dynamics damping="10.0"/>
  </joint>
  <link name="right_shoulder_1">
    <visual>
      <geometry>
        <mesh filename="package://mybot_description/dae/right_shoulder_1.dae"/>
      </geometry>
      <material name="gray">
        <color rgba="0.8 0.8 0.8 1"/>
      </material>
    </visual>
    <collision>
      <geometry>
        <mesh filename="package://mybot_description/dae/right_shoulder_1.dae"/>
      </geometry>
    </collision>
  </link>
  <joint name="right_shoulder_joint_2" type="revolute">
    <parent link="right_shoulder_1"/>
    <child link="right_shoulder_2"/>
    <axis xyz="-1 0 0"/>
    <origin rpy="0 0 0" xyz="0 -0.162 0"/>
    <limit effort="30.0" lower="-0.0" upper="1.57079632679" velocity="0.418879020479"/>
    <dynamics damping="10.0"/>
  </joint>
  <link name="right_shoulder_2">
    <visual>
      <geometry>
        <mesh filename="package://mybot_description/dae/right_shoulder_2.dae"/>
      </geometry>
      <material name="gray">
        <color rgba="0.8 0.8 0.8 1"/>
      </material>
    </visual>
    <collision>
      <geometry>
        <mesh filename="package://mybot_description/dae/right_shoulder_2.dae"/>
      </geometry>
    </collision>
  </link>
  <joint name="right_shoulder_joint_3" type="revolute">
    <parent link="right_shoulder_2"/>
    <child link="right_shoulder_3"/>
    <axis xyz="0 0 -1"/>
    <origin rpy="0 0 0" xyz="0 0 0"/>
    <limit effort="30.0" lower="-1.57079632679" upper="0.523598775598" velocity="0.418879020479"/>
    <dynamics damping="10.0"/>
  </joint>
  <link name="right_shoulder_3">
    <visual>
      <geometry>
        <mesh filename="package://mybot_description/dae/right_shoulder_3.dae"/>
      </geometry>
      <material name="gray">
        <color rgba="0.8 0.8 0.8 1"/>
      </material>
    </visual>
    <collision>
      <geometry>
        <mesh filename="package://mybot_description/dae/right_shoulder_3.dae"/>
      </geometry>
    </collision>
  </link>
  <joint name="right_elbow_joint_0" type="revolute">
    <parent link="right_shoulder_3"/>
    <child link="right_elbow_0"/>
    <axis xyz="0 -1 0"/>
    <origin rpy="0 0 0" xyz="0 0 -0.204"/>
    <limit effort="30.0" lower="-0.0" upper="1.57079632679" velocity="0.418879020479"/>
    <dynamics damping="10.0"/>
  </joint>
  <link name="right_elbow_0">
    <visual>
      <geometry>
        <mesh filename="package://mybot_description/dae/right_elbow_0.dae"/>
      </geometry>
      <material name="gray">
        <color rgba="0.8 0.8 0.8 1"/>
      </material>
    </visual>
    <collision>
      <geometry>
        <mesh filename="package://mybot_description/dae/right_elbow_0.dae"/>
      </geometry>
    </collision>
  </link>
  <joint name="right_wrist_joint_0" type="revolute">
    <parent link="right_elbow_0"/>
    <child link="right_wrist_0"/>
    <axis xyz="0 0 -1"/>
    <origin rpy="0 0 0" xyz="0 0 0"/>
    <limit effort="30.0" lower="-2.09439510239" upper="2.09439510239" velocity="0.418879020479"/>
    <dynamics damping="10.0"/>
  </joint>
  <link name="right_wrist_0">
    <visual>
      <geometry>
        <mesh filename="package://mybot_description/dae/right_wrist_0.dae"/>
      </geometry>
      <material name="gray">
        <color rgba="0.8 0.8 0.8 1"/>
      </material>
    </visual>
    <collision>
      <geometry>
        <mesh filename="package://mybot_description/dae/right_wrist_0.dae"/>
      </geometry>
    </collision>
  </link>
  <joint name="right_wrist_joint_1" type="revolute">
    <parent link="right_wrist_0"/>
    <child link="right_wrist_1"/>
    <axis xyz="1 0 0"/>
    <origin rpy="0 0 0" xyz="0 0 -0.2735"/>
    <limit effort="30.0" lower="-1.0471975512" upper="1.0471975512" velocity="0.418879020479"/>
    <dynamics damping="10.0"/>
  </joint>
  <link name="right_wrist_1">
    <visual>
      <geometry>
        <mesh filename="package://mybot_description/dae/right_wrist_1.dae"/>
      </geometry>
      <material name="gray">
        <color rgba="0.8 0.8 0.8 1"/>
      </material>
    </visual>
    <collision>
      <geometry>
        <mesh filename="package://mybot_description/dae/right_wrist_1.dae"/>
      </geometry>
    </collision>
  </link>
  <joint name="right_wrist_joint_2" type="revolute">
    <parent link="right_wrist_1"/>
    <child link="right_wrist_2"/>
    <axis xyz="0 -1 0"/>
    <origin rpy="0 0 0" xyz="0 0 0"/>
    <limit effort="30.0" lower="-0.523598775598" upper="0.523598775598" velocity="0.418879020479"/>
    <dynamics damping="10.0"/>
  </joint>
  <link name="right_wrist_2">
    <visual>
      <geometry>
        <mesh filename="package://mybot_description/dae/right_wrist_2.dae"/>
      </geometry>
      <material name="gray">
        <color rgba="0.8 0.8 0.8 1"/>
      </material>
    </visual>
    <collision>
      <geometry>
        <mesh filename="package://mybot_description/dae/right_wrist_2.dae"/>
      </geometry>
    </collision>
  </link>
  <!-- LEFT ARM -->
  <joint name="left_shoulder_joint_0" type="revolute">
    <parent link="waist_1"/>
    <child link="left_shoulder_0"/>
    <axis xyz="0 0 1"/>
    <origin rpy="0 0 0" xyz="0 0.075 0.351"/>
    <limit effort="30.0" lower="-1.0471975512" upper="1.0471975512" velocity="0.418879020479"/>
    <dynamics damping="10.0"/>
  </joint>
  <link name="left_shoulder_0">
    <visual>
      <geometry>
        <mesh filename="package://mybot_description/dae/left_shoulder_0.dae"/>
      </geometry>
      <material name="gray">
        <color rgba="0.8 0.8 0.8 1"/>
      </material>
    </visual>
    <collision>
      <geometry>
        <mesh filename="package://mybot_description/dae/left_shoulder_0.dae"/>
      </geometry>
    </collision>
  </link>
  <joint name="left_shoulder_joint_1" type="revolute">
    <parent link="left_shoulder_0"/>
    <child link="left_shoulder_1"/>
    <axis xyz="0 1 0"/>
    <origin rpy="0 0 0" xyz="0 0 0"/>
    <limit effort="30.0" lower="-2.09439510239" upper="1.57079632679" velocity="0.418879020479"/>
    <dynamics damping="10.0"/>
  </joint>
  <link name="left_shoulder_1">
    <visual>
      <geometry>
        <mesh filename="package://mybot_description/dae/left_shoulder_1.dae"/>
      </geometry>
      <material name="gray">
        <color rgba="0.8 0.8 0.8 1"/>
      </material>
    </visual>
    <collision>
      <geometry>
        <mesh filename="package://mybot_description/dae/left_shoulder_1.dae"/>
      </geometry>
    </collision>
  </link>
  <joint name="left_shoulder_joint_2" type="revolute">
    <parent link="left_shoulder_1"/>
    <child link="left_shoulder_2"/>
    <axis xyz="-1 0 0"/>
    <origin rpy="0 0 0" xyz="0 0.162 0"/>
    <limit effort="30.0" lower="-1.57079632679" upper="0.0" velocity="0.418879020479"/>
    <dynamics damping="10.0"/>
  </joint>
  <link name="left_shoulder_2">
    <visual>
      <geometry>
        <mesh filename="package://mybot_description/dae/left_shoulder_2.dae"/>
      </geometry>
      <material name="gray">
        <color rgba="0.8 0.8 0.8 1"/>
      </material>
    </visual>
    <collision>
      <geometry>
        <mesh filename="package://mybot_description/dae/left_shoulder_2.dae"/>
      </geometry>
    </collision>
  </link>
  <joint name="left_shoulder_joint_3" type="revolute">
    <parent link="left_shoulder_2"/>
    <child link="left_shoulder_3"/>
    <axis xyz="0 0 -1"/>
    <origin rpy="0 0 0" xyz="0 0 0"/>
    <limit effort="30.0" lower="-0.523598775598" upper="1.57079632679" velocity="0.418879020479"/>
    <dynamics damping="10.0"/>
  </joint>
  <link name="left_shoulder_3">
    <visual>
      <geometry>
        <mesh filename="package://mybot_description/dae/left_shoulder_3.dae"/>
      </geometry>
      <material name="gray">
        <color rgba="0.8 0.8 0.8 1"/>
      </material>
    </visual>
    <collision>
      <geometry>
        <mesh filename="package://mybot_description/dae/left_shoulder_3.dae"/>
      </geometry>
    </collision>
  </link>
  <joint name="left_elbow_joint_0" type="revolute">
    <parent link="left_shoulder_3"/>
    <child link="left_elbow_0"/>
    <axis xyz="0 1 0"/>
    <origin rpy="0 0 0" xyz="0 0 -0.204"/>
    <limit effort="30.0" lower="-1.57079632679" upper="0.0" velocity="0.418879020479"/>
    <dynamics damping="10.0"/>
  </joint>
  <link name="left_elbow_0">
    <visual>
      <geometry>
        <mesh filename="package://mybot_description/dae/left_elbow_0.dae"/>
      </geometry>
      <material name="gray">
        <color rgba="0.8 0.8 0.8 1"/>
      </material>
    </visual>
    <collision>
      <geometry>
        <mesh filename="package://mybot_description/dae/left_elbow_0.dae"/>
      </geometry>
    </collision>
  </link>
  <joint name="left_wrist_joint_0" type="revolute">
    <parent link="left_elbow_0"/>
    <child link="left_wrist_0"/>
    <axis xyz="0 0 -1"/>
    <origin rpy="0 0 0" xyz="0 0 0"/>
    <limit effort="30.0" lower="-2.09439510239" upper="2.09439510239" velocity="0.418879020479"/>
    <dynamics damping="10.0"/>
  </joint>
  <link name="left_wrist_0">
    <visual>
      <geometry>
        <mesh filename="package://mybot_description/dae/left_wrist_0.dae"/>
      </geometry>
      <material name="gray">
        <color rgba="0.8 0.8 0.8 1"/>
      </material>
    </visual>
    <collision>
      <geometry>
        <mesh filename="package://mybot_description/dae/left_wrist_0.dae"/>
      </geometry>
    </collision>
  </link>
  <joint name="left_wrist_joint_1" type="revolute">
    <parent link="left_wrist_0"/>
    <child link="left_wrist_1"/>
    <axis xyz="1 0 0"/>
    <origin rpy="0 0 0" xyz="0 0 -0.2735"/>
    <limit effort="30.0" lower="-1.0471975512" upper="1.0471975512" velocity="0.418879020479"/>
    <dynamics damping="10.0"/>
  </joint>
  <link name="left_wrist_1">
    <visual>
      <geometry>
        <mesh filename="package://mybot_description/dae/left_wrist_1.dae"/>
      </geometry>
      <material name="gray">
        <color rgba="0.8 0.8 0.8 1"/>
      </material>
    </visual>
    <collision>
      <geometry>
        <mesh filename="package://mybot_description/dae/left_wrist_1.dae"/>
      </geometry>
    </collision>
  </link>
  <joint name="left_wrist_joint_2" type="revolute">
    <parent link="left_wrist_1"/>
    <child link="left_wrist_2"/>
    <axis xyz="0 -1 0"/>
    <origin rpy="0 0 0" xyz="0 0 0"/>
    <limit effort="30.0" lower="-0.523598775598" upper="0.523598775598" velocity="0.418879020479"/>
    <dynamics damping="10.0"/>
  </joint>
  <link name="left_wrist_2">
    <visual>
      <geometry>
        <mesh filename="package://mybot_description/dae/left_wrist_2.dae"/>
      </geometry>
      <material name="gray">
        <color rgba="0.8 0.8 0.8 1"/>
      </material>
    </visual>
    <collision>
      <geometry>
        <mesh filename="package://mybot_description/dae/left_wrist_2.dae"/>
      </geometry>
    </collision>
  </link>
  <!-- RIGHT GRIPPER -->
  <joint name="right_gripper_parm_joint_0" type="fixed">
    <parent link="right_wrist_2"/>
    <child link="right_gripper_parm_0"/>
    <origin rpy="0.785 0 0" xyz="0 0.06046 -0.14234"/>
  </joint>
  <link name="right_gripper_parm_0">
    <visual>
      <geometry>
        <mesh filename="package://mybot_description/dae/right_gripper_parm_0.dae"/>
      </geometry>
      <material name="gray">
        <color rgba="0.8 0.8 0.8 1"/>
      </material>
    </visual>
    <collision>
      <geometry>
        <mesh filename="package://mybot_description/dae/right_gripper_parm_0.dae"/>
      </geometry>
    </collision>
  </link>
  <joint name="right_gripper_parm_joint_1" type="fixed">
    <parent link="right_gripper_parm_0"/>
    <child link="right_gripper_parm_1"/>
    <origin rpy="-0.785 0 0" xyz="0 0 0"/>
  </joint>
  <link name="right_gripper_parm_1"/>
  <joint name="right_gripper_thumb_joint_0" type="revolute">
    <parent link="right_gripper_parm_1"/>
    <child link="right_gripper_thumb_0"/>
    <axis xyz="-1 0 0"/>
    <origin xyz="0 -0.03652 0.06381"/>
    <limit effort="30.0" lower="-0.349065850399" upper="0.174532925199" velocity="0.418879020479"/>
    <dynamics damping="10.0"/>
  </joint>
  <link name="right_gripper_thumb_0">
    <visual>
      <geometry>
        <mesh filename="package://mybot_description/dae/right_gripper_thumb_0.dae"/>
      </geometry>
      <material name="gray">
        <color rgba="0.8 0.8 0.8 1"/>
      </material>
    </visual>
    <collision>
      <geometry>
        <mesh filename="package://mybot_description/dae/right_gripper_thumb_0.dae"/>
      </geometry>
    </collision>
  </link>
  <joint name="right_gripper_thumb_joint_1" type="revolute">
    <parent link="right_gripper_thumb_0"/>
    <child link="right_gripper_thumb_1"/>
    <axis xyz="-1 0 0"/>
    <origin rpy="0 0 0" xyz="0 0.04698 -0.01639"/>
    <mimic joint="right_gripper_thumb_joint_0" multiplier="2"/>
    <limit effort="30.0" lower="-0.698131700798" upper="0.349065850399" velocity="0.418879020479"/>
    <dynamics damping="10.0"/>
  </joint>
  <link name="right_gripper_thumb_1">
    <visual>
      <geometry>
        <mesh filename="package://mybot_description/dae/right_gripper_thumb_1.dae"/>
      </geometry>
      <material name="gray">
        <color rgba="0.8 0.8 0.8 1"/>
      </material>
    </visual>
    <collision>
      <geometry>
        <mesh filename="package://mybot_description/dae/right_gripper_thumb_1.dae"/>
      </geometry>
    </collision>
  </link>
  <joint name="right_gripper_forefinger_joint_0" type="revolute">
    <parent link="right_gripper_parm_1"/>
    <child link="right_gripper_forefinger_0"/>
    <axis xyz="1 0 0"/>
    <origin rpy="0 0 0" xyz="0 -0.06381 0.03652"/>
    <limit effort="30.0" lower="-0.349065850399" upper="0.174532925199" velocity="0.418879020479"/>
    <dynamics damping="10.0"/>
  </joint>
  <link name="right_gripper_forefinger_0">
    <visual>
      <geometry>
        <mesh filename="package://mybot_description/dae/right_gripper_forefinger_0.dae"/>
      </geometry>
      <material name="gray">
        <color rgba="0.8 0.8 0.8 1"/>
      </material>
    </visual>
    <collision>
      <geometry>
        <mesh filename="package://mybot_description/dae/right_gripper_forefinger_0.dae"/>
      </geometry>
    </collision>
  </link>
  <joint name="right_gripper_forefinger_joint_1" type="revolute">
    <parent link="right_gripper_forefinger_0"/>
    <child link="right_gripper_forefinger_1"/>
    <axis xyz="1 0 0"/>
    <origin rpy="0 0 0" xyz="0 0.01639 -0.04698"/>
    <mimic joint="right_gripper_forefinger_joint_0" multiplier="2"/>
    <limit effort="30.0" lower="-0.698131700798" upper="0.349065850399" velocity="0.418879020479"/>
    <dynamics damping="10.0"/>
  </joint>
  <link name="right_gripper_forefinger_1">
    <visual>
      <geometry>
        <mesh filename="package://mybot_description/dae/right_gripper_forefinger_1.dae"/>
      </geometry>
      <material name="gray">
        <color rgba="0.8 0.8 0.8 1"/>
      </material>
    </visual>
    <collision>
      <geometry>
        <mesh filename="package://mybot_description/dae/right_gripper_forefinger_1.dae"/>
      </geometry>
    </collision>
  </link>
  <joint name="right_gripper_littlefinger_joint_0" type="revolute">
    <parent link="right_gripper_parm_1"/>
    <child link="right_gripper_littlefinger_0"/>
    <axis xyz="-1 0 0"/>
    <origin rpy="0 0 0" xyz="0 -0.06381 0.03652"/>
    <limit effort="30.0" lower="-0.174532925199" upper="0.349065850399" velocity="0.418879020479"/>
    <dynamics damping="10.0"/>
  </joint>
  <link name="right_gripper_littlefinger_0">
    <visual>
      <geometry>
        <mesh filename="package://mybot_description/dae/right_gripper_littlefinger_0.dae"/>
      </geometry>
      <material name="gray">
        <color rgba="0.8 0.8 0.8 1"/>
      </material>
    </visual>
    <collision>
      <geometry>
        <mesh filename="package://mybot_description/dae/right_gripper_littlefinger_0.dae"/>
      </geometry>
    </collision>
  </link>
  <joint name="right_gripper_littlefinger_joint_1" type="revolute">
    <parent link="right_gripper_littlefinger_0"/>
    <child link="right_gripper_littlefinger_1"/>
    <axis xyz="-1 0 0"/>
    <origin rpy="0 0 0" xyz="0 0.01639 -0.04698"/>
    <mimic joint="right_gripper_littlefinger_joint_0" multiplier="2"/>
    <limit effort="30.0" lower="-0.349065850399" upper="0.698131700798" velocity="0.418879020479"/>
    <dynamics damping="10.0"/>
  </joint>
  <link name="right_gripper_littlefinger_1">
    <visual>
      <geometry>
        <mesh filename="package://mybot_description/dae/right_gripper_littlefinger_1.dae"/>
      </geometry>
      <material name="gray">
        <color rgba="0.8 0.8 0.8 1"/>
      </material>
    </visual>
    <collision>
      <geometry>
        <mesh filename="package://mybot_description/dae/right_gripper_littlefinger_1.dae"/>
      </geometry>
    </collision>
  </link>
  <!-- LEFT GRIPPER -->
  <joint name="left_gripper_parm_joint_0" type="fixed">
    <parent link="left_wrist_2"/>
    <child link="left_gripper_parm_0"/>
    <origin rpy="-0.785 0 0" xyz="0 -0.06046 -0.14234"/>
  </joint>
  <link name="left_gripper_parm_0">
    <visual>
      <geometry>
        <mesh filename="package://mybot_description/dae/left_gripper_parm_0.dae"/>
      </geometry>
      <material name="gray">
        <color rgba="0.8 0.8 0.8 1"/>
      </material>
    </visual>
    <collision>
      <geometry>
        <mesh filename="package://mybot_description/dae/left_gripper_parm_0.dae"/>
      </geometry>
    </collision>
  </link>
  <joint name="left_gripper_parm_joint_1" type="fixed">
    <parent link="left_gripper_parm_0"/>
    <child link="left_gripper_parm_1"/>
    <origin rpy="0.785 0 0" xyz="0 0 0"/>
  </joint>
  <link name="left_gripper_parm_1"/>
  <joint name="left_gripper_thumb_joint_0" type="revolute">
    <parent link="left_gripper_parm_1"/>
    <child link="left_gripper_thumb_0"/>
    <axis xyz="-1 0 0"/>
    <origin xyz="0 0.03652 0.06381"/>
    <limit effort="30.0" lower="-0.174532925199" upper="0.349065850399" velocity="0.418879020479"/>
    <dynamics damping="10.0"/>
  </joint>
  <link name="left_gripper_thumb_0">
    <visual>
      <geometry>
        <mesh filename="package://mybot_description/dae/left_gripper_thumb_0.dae"/>
      </geometry>
      <material name="gray">
        <color rgba="0.8 0.8 0.8 1"/>
      </material>
    </visual>
    <collision>
      <geometry>
        <mesh filename="package://mybot_description/dae/left_gripper_thumb_0.dae"/>
      </geometry>
    </collision>
  </link>
  <joint name="left_gripper_thumb_joint_1" type="revolute">
    <parent link="left_gripper_thumb_0"/>
    <child link="left_gripper_thumb_1"/>
    <axis xyz="-1 0 0"/>
    <origin rpy="0 0 0" xyz="0 -0.04698 -0.01639"/>
    <mimic joint="left_gripper_thumb_joint_0" multiplier="2"/>
    <limit effort="30.0" lower="-0.349065850399" upper="0.698131700798" velocity="0.418879020479"/>
    <dynamics damping="10.0"/>
  </joint>
  <link name="left_gripper_thumb_1">
    <visual>
      <geometry>
        <mesh filename="package://mybot_description/dae/left_gripper_thumb_1.dae"/>
      </geometry>
      <material name="gray">
        <color rgba="0.8 0.8 0.8 1"/>
      </material>
    </visual>
    <collision>
      <geometry>
        <mesh filename="package://mybot_description/dae/left_gripper_thumb_1.dae"/>
      </geometry>
    </collision>
  </link>
  <joint name="left_gripper_forefinger_joint_0" type="revolute">
    <parent link="left_gripper_parm_1"/>
    <child link="left_gripper_forefinger_0"/>
    <axis xyz="1 0 0"/>
    <origin rpy="0 0 0" xyz="0 0.06381 0.03652"/>
    <limit effort="30.0" lower="-0.174532925199" upper="0.349065850399" velocity="0.418879020479"/>
    <dynamics damping="10.0"/>
  </joint>
  <link name="left_gripper_forefinger_0">
    <visual>
      <geometry>
        <mesh filename="package://mybot_description/dae/left_gripper_forefinger_0.dae"/>
      </geometry>
      <material name="gray">
        <color rgba="0.8 0.8 0.8 1"/>
      </material>
    </visual>
    <collision>
      <geometry>
        <mesh filename="package://mybot_description/dae/left_gripper_forefinger_0.dae"/>
      </geometry>
    </collision>
  </link>
  <joint name="left_gripper_forefinger_joint_1" type="revolute">
    <parent link="left_gripper_forefinger_0"/>
    <child link="left_gripper_forefinger_1"/>
    <axis xyz="1 0 0"/>
    <origin rpy="0 0 0" xyz="0 -0.01639 -0.04698"/>
    <mimic joint="left_gripper_forefinger_joint_0" multiplier="2"/>
    <limit effort="30.0" lower="-0.349065850399" upper="0.698131700798" velocity="0.418879020479"/>
    <dynamics damping="10.0"/>
  </joint>
  <link name="left_gripper_forefinger_1">
    <visual>
      <geometry>
        <mesh filename="package://mybot_description/dae/left_gripper_forefinger_1.dae"/>
      </geometry>
      <material name="gray">
        <color rgba="0.8 0.8 0.8 1"/>
      </material>
    </visual>
    <collision>
      <geometry>
        <mesh filename="package://mybot_description/dae/left_gripper_forefinger_1.dae"/>
      </geometry>
    </collision>
  </link>
  <joint name="left_gripper_littlefinger_joint_0" type="revolute">
    <parent link="left_gripper_parm_1"/>
    <child link="left_gripper_littlefinger_0"/>
    <axis xyz="-1 0 0"/>
    <origin rpy="0 0 0" xyz="0 0.06381 0.03652"/>
    <limit effort="30.0" lower="-0.349065850399" upper="0.174532925199" velocity="0.418879020479"/>
    <dynamics damping="10.0"/>
  </joint>
  <link name="left_gripper_littlefinger_0">
    <visual>
      <geometry>
        <mesh filename="package://mybot_description/dae/left_gripper_littlefinger_0.dae"/>
      </geometry>
      <material name="gray">
        <color rgba="0.8 0.8 0.8 1"/>
      </material>
    </visual>
    <collision>
      <geometry>
        <mesh filename="package://mybot_description/dae/left_gripper_littlefinger_0.dae"/>
      </geometry>
    </collision>
  </link>
  <joint name="left_gripper_littlefinger_joint_1" type="revolute">
    <parent link="left_gripper_littlefinger_0"/>
    <child link="left_gripper_littlefinger_1"/>
    <axis xyz="-1 0 0"/>
    <origin rpy="0 0 0" xyz="0 -0.01639 -0.04698"/>
    <mimic joint="left_gripper_littlefinger_joint_0" multiplier="2"/>
    <limit effort="30.0" lower="-0.698131700798" upper="0.349065850399" velocity="0.418879020479"/>
    <dynamics damping="10.0"/>
  </joint>
  <link name="left_gripper_littlefinger_1">
    <visual>
      <geometry>
        <mesh filename="package://mybot_description/dae/left_gripper_littlefinger_1.dae"/>
      </geometry>
      <material name="gray">
        <color rgba="0.8 0.8 0.8 1"/>
      </material>
    </visual>
    <collision>
      <geometry>
        <mesh filename="package://mybot_description/dae/left_gripper_littlefinger_1.dae"/>
      </geometry>
    </collision>
  </link>
  <!-- BOTTLE MOUTH -->
  <joint name="right_bottle_mouth_joint" type="fixed">
    <parent link="right_gripper_parm_0"/>
    <child link="right_bottle_mouth"/>
    <origin rpy="0 0 0" xyz="0 0 0"/>
  </joint>
  <link name="right_bottle_mouth"/>
  <joint name="left_bottle_mouth_joint" type="fixed">
    <parent link="left_gripper_parm_0"/>
    <child link="left_bottle_mouth"/>
    <origin rpy="0 0 0" xyz="0 0 0"/>
  </joint>
  <link name="left_bottle_mouth"/>
</robot>
